Workbook
Name DvListSource1: [1]Sheet2!$B$1:$B$57
Name DvListSource10: [1]Sheet2!$AJ$1:$AJ$27
Name DvListSource11: [1]Sheet2!$AK$1:$AK$5574
Name DvListSource12: [1]Sheet2!$AP$1:$AP$6
Name DvListSource2: [1]Sheet2!$D$1:$D$7
Name DvListSource3: [1]Sheet2!$Z$1:$Z$4
Name DvListSource4: [1]Sheet2!$AA$1:$AA$6
Name DvListSource5: [1]Sheet2!$AE$1:$AE$16
Name DvListSource6: [1]Sheet2!$AF$1:$AF$10
Name DvListSource7: [1]Sheet2!$AG$1
Name DvListSource8: [1]Sheet2!$AH$1
Name DvListSource9: [1]Sheet2!$AI$1:$AI$54

Sheet BASE RECEBIMENTOS
A1: Tipo de doc | B1: Empresa | C1: Código do cliente/fornecedor | D1: Fornecedor | E1: Item do FLuxo de Caixa | F1: Data de Lançamento | G1: Data do Documento | H1: N° da Nota Fiscal | I1: Data do Vencimento | J1: Parcela | K1: Total faltando | L1: DataPg | M1: Juros/Desconto | N1: Total Recebido | O1: Tipo | P1: Nome da Conta | Q1: Observação do lançamento | R1: Criado mediante execução do pagamento | S1: =IF(C1="","",_xlfn.IFNA(_xlfn.XLOOKUP(C1,'CADASTRO CLIENTE'!$B$2:$B$9815,'CADASTRO CLIENTE'!$C$2:$C$9815),"NÃO ENCONTRADO")) -> NÃO ENCONTRADO
A2: NS | B2: KROMA COMERCIALIZADORA DE ENERGIA LTDA | C2: C01145 | D2: INDRA COMERCIALIZADORA DE ENERGIAS LIMITADA | F2: 46301 | G2: 46301 | H2: 51696 | I2: 46303 | J2: 46023 | K2: 0 | L2: 46303 | M2: 0 | N2: 121119.84 | O2: Transferencia | P2: (C) BANCO BRADESCO AG. 2960-2 C/ 116071-0 | Q2: REF RECEB - CR: 4559 - NF: 51696 - PN: INDRA COMERCIALIZADORA DE ENERGIAS LIMITADA | R2: Recebido | S2: =IF(C2="","",_xlfn.IFNA(_xlfn.XLOOKUP(C2,'CADASTRO CLIENTE'!$B$2:$B$9815,'CADASTRO CLIENTE'!$C$2:$C$9815),"NÃO ENCONTRADO")) -> INDRA COMERCIALIZADORA
A3: LC | B3: KROMA COMERCIALIZADORA DE ENERGIA LTDA | C3: C03174 | D3: BRADESCO COMERCIALIZADORA DE ENERGIA LTDA. | K3: 0 | L3: 46234 | M3: 0 | N3: 62004797 | O3: Transferencia | P3: (T) BANCO BRADESCO AG. 2960-2 C/ 116071-0 | Q3: REF RECEB - CR: 959 - LC: 2972 - PN: BRADESCO COMERCIALIZADORA DE ENERGIA LTDA. | R3: Recebido | S3: =IF(C3="","",_xlfn.IFNA(_xlfn.XLOOKUP(C3,'CADASTRO CLIENTE'!$B$2:$B$9815,'CADASTRO CLIENTE'!$C$2:$C$9815),"NÃO ENCONTRADO")) -> BRADESCO COMERCIALIZADORA
A4: NS | B4: KROMA COMERCIALIZADORA DE ENERGIA LTDA | C4: C01767 | D4: CONDOMINIO DO EDIFICIO EMPRESARIAL JMF E JQM | F4: 46244 | G4: 46244 | H4: 50107 | I4: 46244 | J4: 46023 | K4: 0 | L4: 46244 | M4: 0 | N4: 185542.34 | O4: Transferencia | P4: (C) BANCO BRADESCO AG. 2960-2 C/ 116071-0 | Q4: REF RECEB - CR: 1119 - NF: 50107 - PN: CONDOMINIO DO EDIFICIO EMPRESARIAL JMF E JQM | R4: Recebido | S4: =IF(C4="","",_xlfn.IFNA(_xlfn.XLOOKUP(C4,'CADASTRO CLIENTE'!$B$2:$B$9815,'CADASTRO CLIENTE'!$C$2:$C$9815),"NÃO ENCONTRADO")) -> CONDOMÍNIO JMF E JQM
A5: NS | B5: KROMA GESTAO E SERVICOS EM ENERGIA ELETRICA LTDA - EPP | C5: C02950 | D5: TABATINGA AQUACULTURA LTDA | F5: 46267 | G5: 46267 | H5: 1122 | I5: 46295 | J5: 46023 | K5: 0 | L5: 46281 | M5: 0 | N5: 938.5 | O5: Transferencia | P5: (C) BANCO BRADESCO AG. 2960-2 C/ 225-9 | Q5: REF RECEB - CR: 3748 - NF: 1122 - PN: TABATINGA AQUACULTURA LTDA | R5: Recebido | S5: =IF(C5="","",_xlfn.IFNA(_xlfn.XLOOKUP(C5,'CADASTRO CLIENTE'!$B$2:$B$9815,'CADASTRO CLIENTE'!$C$2:$C$9815),"NÃO ENCONTRADO")) -> TABATINGA AQUACULTURA
A6: LC | B6: KROMA GESTAO E SERVICOS EM ENERGIA ELETRICA LTDA - EPP | C6: C02446 | D6: OK DOUTOR CONSULTORIOS MEDICOS LTDA. | K6: 0 | L6: 46204 | M6: 0 | N6: 502.27 | O6: Transferencia | P6: (C) BANCO BRADESCO AG. 2960-2 C/ 225-9 | Q6: REF RECEB - CR: 2112 - LC: 12409 - PN: OK DOUTOR CONSULTORIOS MEDICOS LTDA. | R6: Recebido | S6: =IF(C6="","",_xlfn.IFNA(_xlfn.XLOOKUP(C6,'CADASTRO CLIENTE'!$B$2:$B$9815,'CADASTRO CLIENTE'!$C$2:$C$9815),"NÃO ENCONTRADO")) -> OK DOUTOR CONSULTORIOS MEDICOS
A7: NS | B7: FILIAL - CE - KROMA COMERCIALIZADORA DE ENERGIA LTDA | C7: C01421 | D7: SUPERMERCADO COMETA LTDA | F7: 46239 | G7: 46239 | H7: 1117 | I7: 46244 | J7: 46023 | K7: 0 | L7: 46244 | M7: 0 | N7: 16696.85 | O7: Transferencia | P7: (C) BANCO BRADESCO AG. 2960 C/ 3222-0 | Q7: REF RECEB - CR: 1335 - NF: 1117 - PN: SUPERMERCADO COMETA LTDA | R7: Recebido | S7: =IF(C7="","",_xlfn.IFNA(_xlfn.XLOOKUP(C7,'CADASTRO CLIENTE'!$B$2:$B$9815,'CADASTRO CLIENTE'!$C$2:$C$9815),"NÃO ENCONTRADO")) -> COMETA - VILA PERY (LOJA 23)
A8: NS | B8: KROMA COMERCIALIZADORA DE ENERGIA LTDA | C8: C00909 | D8: SER EDUCACIONAL S.A. | F8: 46261 | G8: 46261 | H8: 2026082701 | I8: 46268 | J8: 46023 | K8: 0 | L8: 46267 | M8: 0 | N8: 515.16 | O8: Transferencia | P8: (C) BANCO BRADESCO AG. 2960-2 C/ 116071-0 | Q8: REF RECEB - CR: 2845 - NF: 2026082701 - PN: SER EDUCACIONAL S.A. | R8: Recebido | S8: =IF(C8="","",_xlfn.IFNA(_xlfn.XLOOKUP(C8,'CADASTRO CLIENTE'!$B$2:$B$9815,'CADASTRO CLIENTE'!$C$2:$C$9815),"NÃO ENCONTRADO")) -> SER - GRAÇAS
A9: NS | B9: SAO PEDRO E PAULO I SPE SA | C9: C03372 | D9: ENERGISA MATO GROSSO DO SUL - DISTRIBUIDORA DE ENERGIA S.A. | F9: 46209 | G9: 46209 | H9: 1446 | I9: 46218 | J9: 46023 | K9: 0 | L9: 46218 | M9: 0 | N9: 12317.29 | O9: Transferencia | P9: (C) BANCO BRADESCO AG. 2960 C/C 219-4 | Q9: REF RECEB - CR: 877 - NF: 1446 - PN: ENERGISA MATO GROSSO DO SUL - DISTRIBUIDORA DE ENERGIA S.A. | R9: Recebido | S9: =IF(C9="","",_xlfn.IFNA(_xlfn.XLOOKUP(C9,'CADASTRO CLIENTE'!$B$2:$B$9815,'CADASTRO CLIENTE'!$C$2:$C$9815),"NÃO ENCONTRADO")) -> ENERGISA MS
A10: NS | B10: KROMA COMERCIALIZADORA DE ENERGIA LTDA | C10: C02228 | D10: APEL ATIVIDADES PRO ENSINO LTDA | F10: 46206 | G10: 46206 | H10: 48728 | I10: 46211 | J10: 46023 | K10: 0 | L10: 46210 | M10: 0 | N10: 1556.16 | O10: Transferencia | P10: (C) BANCO BRADESCO AG. 2960-2 C/ 116071-0 | Q10: REF RECEB - CR: 259 - NF: 48728 - PN: APEL ATIVIDADES PRO ENSINO LTDA | R10: Recebido | S10: =IF(C10="","",_xlfn.IFNA(_xlfn.XLOOKUP(C10,'CADASTRO CLIENTE'!$B$2:$B$9815,'CADASTRO CLIENTE'!$C$2:$C$9815),"NÃO ENCONTRADO")) -> COLEGIO CHRISTUS - SIL. PAULET
A11: NS | B11: KROMA COMERCIALIZADORA DE ENERGIA LTDA | C11: C00109 | D11: CEMIG GERACAO E TRANSMISSAO S.A | F11: 46237 | G11: 46237 | H11: 49423 | I11: 46244 | J11: 46023 | K11: 0 | L11: 46244 | M11: 0 | N11: 766989.6 | O11: Transferencia | P11: (C) BANCO BRADESCO AG. 2960-2 C/ 116071-0 | Q11: REF RECEB - CR: 1320 - NF: 49423 - PN: CEMIG GERACAO E TRANSMISSAO S.A | R11: Recebido | S11: =IF(C11="","",_xlfn.IFNA(_xlfn.XLOOKUP(C11,'CADASTRO CLIENTE'!$B$2:$B$9815,'CADASTRO CLIENTE'!$C$2:$C$9815),"NÃO ENCONTRADO")) -> CEMIG
A12: NS | B12: UFV FLIP PRATA SPE S.A. | C12: C03466 | D12: GISELDA MARIA TORREAS DA LUZ | F12: 46252 | G12: 46252 | H12: 133 | I12: 46252 | J12: 46023 | K12: 0 | L12: 46308 | M12: 0 | N12: 355.66 | O12: Transferencia | P12: (C) BANCO BRADESCO AG 2960 CC 3193-3 | Q12: REF RECEB - CR: 5256 - NF: 133 - PN: GISELDA MARIA TORREAS DA LUZ | R12: Recebido | S12: =IF(C12="","",_xlfn.IFNA(_xlfn.XLOOKUP(C12,'CADASTRO CLIENTE'!$B$2:$B$9815,'CADASTRO CLIENTE'!$C$2:$C$9815),"NÃO ENCONTRADO")) -> 0
A13: NS | B13: KROMA COMERCIALIZADORA DE ENERGIA LTDA | C13: C03392 | D13: SERVICO NACIONAL DE APRENDIZAGEM INDUSTRIAL | F13: 46206 | G13: 46206 | H13: 48654 | I13: 46211 | J13: 46023 | K13: 0 | L13: 46211 | M13: 0 | N13: 2704.02 | O13: Transferencia | P13: (C) BANCO BRADESCO AG. 2960-2 C/ 116071-0 | Q13: REF RECEB - CR: 24 - NF: 48654 - PN: SERVICO NACIONAL DE APRENDIZAGEM INDUSTRIAL | R13: Recebido | S13: =IF(C13="","",_xlfn.IFNA(_xlfn.XLOOKUP(C13,'CADASTRO CLIENTE'!$B$2:$B$9815,'CADASTRO CLIENTE'!$C$2:$C$9815),"NÃO ENCONTRADO")) -> SENAI ARARIPINA
A14: LC | B14: KROMA GESTAO E SERVICOS EM ENERGIA ELETRICA LTDA - EPP | C14: C02271 | D14: UNIAO DE PROFESSORES LTDA | K14: 0 | L14: 46204 | M14: 0 | N14: 716.5 | O14: Transferencia | P14: (C) BANCO BRADESCO AG. 2960-2 C/ 225-9 | Q14: REF RECEB - CR: 2082 - LC: 12366 - PN: UNIAO DE PROFESSORES LTDA | R14: Recebido | S14: =IF(C14="","",_xlfn.IFNA(_xlfn.XLOOKUP(C14,'CADASTRO CLIENTE'!$B$2:$B$9815,'CADASTRO CLIENTE'!$C$2:$C$9815),"NÃO ENCONTRADO")) -> UP - VILA VELHA
A15: NS | B15: KROMA COMERCIALIZADORA DE ENERGIA LTDA | C15: C02943 | D15: BONANZA SUPERMERCADOS LTDA EM RECUPERACAO JUDICIAL | F15: 46302 | G15: 46302 | H15: 51860 | I15: 46307 | J15: 46023 | K15: 0 | L15: 46308 | M15: 0 | N15: 12507.16 | O15: Transferencia | P15: (C) BANCO BNB AG. 44 C/ 49680-0 | Q15: REF RECEB - CR: 4875 - NF: 51860 - PN: BONANZA SUPERMERCADOS LTDA EM RECUPERACAO JUDICIAL | R15: Recebido | S15: =IF(C15="","",_xlfn.IFNA(_xlfn.XLOOKUP(C15,'CADASTRO CLIENTE'!$B$2:$B$9815,'CADASTRO CLIENTE'!$C$2:$C$9815),"NÃO ENCONTRADO")) -> BONANZA - LOJA 02
A16: NS | B16: KROMA COMERCIALIZADORA DE ENERGIA LTDA | C16: C02536 | D16: SELF IT ACADEMIAS HOLDING S.A. | F16: 46239 | G16: 46239 | H16: 49803 | I16: 46248 | J16: 46023 | K16: 0 | L16: 46244 | M16: 0 | N16: 7183.83 | O16: Transferencia | P16: (C) BANCO BRADESCO AG. 2960-2 C/ 116071-0 | Q16: REF RECEB - CR: 1212 - NF: 49803 - PN: SELF IT ACADEMIAS HOLDING S.A. | R16: Recebido | S16: =IF(C16="","",_xlfn.IFNA(_xlfn.XLOOKUP(C16,'CADASTRO CLIENTE'!$B$2:$B$9815,'CADASTRO CLIENTE'!$C$2:$C$9815),"NÃO ENCONTRADO")) -> SELFIT DIRCEU (PI)
A17: NS | B17: KROMA COMERCIALIZADORA DE ENERGIA LTDA | C17: C02538 | D17: ASSUPERO ENSINO SUPERIOR LTDA. | F17: 46300 | G17: 46300 | H17: 51458 | I17: 46310 | J17: 46023 | K17: 0 | L17: 46304 | M17: 0 | N17: 26898.12 | O17: Transferencia | P17: (C) BANCO BRADESCO AG. 2960-2 C/ 116071-0 | Q17: REF RECEB - CR: 4731 - NF: 51458 - PN: ASSUPERO ENSINO SUPERIOR LTDA. | R17: Recebido | S17: =IF(C17="","",_xlfn.IFNA(_xlfn.XLOOKUP(C17,'CADASTRO CLIENTE'!$B$2:$B$9815,'CADASTRO CLIENTE'!$C$2:$C$9815),"NÃO ENCONTRADO")) -> UNIP TERESINA
A18: NS | B18: KROMA COMERCIALIZADORA DE ENERGIA LTDA | C18: C02704 | D18: SOCIEDADE EDUCACIONAL JABAQUARA LTDA. | F18: 46239 | G18: 46239 | H18: 49837 | I18: 46249 | J18: 46023 | K18: 0 | L18: 46251 | M18: 0 | N18: 808.36 | O18: Transferencia | P18: (C) BANCO BRADESCO AG. 2960-2 C/ 116071-0 | Q18: REF RECEB - CR: 1746 - NF: 49837 - PN: SOCIEDADE EDUCACIONAL JABAQUARA LTDA. | R18: Recebido | S18: =IF(C18="","",_xlfn.IFNA(_xlfn.XLOOKUP(C18,'CADASTRO CLIENTE'!$B$2:$B$9815,'CADASTRO CLIENTE'!$C$2:$C$9815),"NÃO ENCONTRADO")) -> INSPIRA - MTE0004324
A19: NS | B19: KROMA COMERCIALIZADORA DE ENERGIA LTDA | C19: C01494 | D19: DUCOCO PRODUTOS ALIMENTICIOS S/A | F19: 46269 | G19: 46269 | H19: 50803 | I19: 46273 | J19: 46023 | K19: 0 | L19: 46274 | M19: 0 | N19: 548788.69 | O19: Transferencia | P19: (C) BANCO BNB AG. 44 C/ 49680-0 | Q19: REF RECEB - CR: 3094 - NF: 50803 - PN: DUCOCO PRODUTOS ALIMENTICIOS S/A | R19: Recebido | S19: =IF(C19="","",_xlfn.IFNA(_xlfn.XLOOKUP(C19,'CADASTRO CLIENTE'!$B$2:$B$9815,'CADASTRO CLIENTE'!$C$2:$C$9815),"NÃO ENCONTRADO")) -> DUCOCO
A20: NS | B20: KROMA COMERCIALIZADORA DE ENERGIA LTDA | C20: C02234 | D20: FORPACK INDUSTRIA DE EMBALAGENS LTDA | F20: 46206 | G20: 46206 | H20: 48618 | I20: 46211 | J20: 46023 | K20: 0 | L20: 46210 | M20: 0 | N20: 12139.93 | O20: Transferencia | P20: (C) BANCO BRADESCO AG. 2960-2 C/ 116071-0 | Q20: REF RECEB - CR: 266 - NF: 48618 - PN: FORPACK INDUSTRIA DE EMBALAGENS LTDA | R20: Recebido | S20: =IF(C20="","",_xlfn.IFNA(_xlfn.XLOOKUP(C20,'CADASTRO CLIENTE'!$B$2:$B$9815,'CADASTRO CLIENTE'!$C$2:$C$9815),"NÃO ENCONTRADO")) -> FORPACK
A21: LC | B21: KROMA COMERCIALIZADORA DE ENERGIA LTDA | C21: C02118 | D21: COMANDO DA MARINHA | K21: 0 | L21: 46234 | M21: 0 | N21: 6221 | O21: Transferencia | P21: (T) BANCO BRADESCO AG. 2960-2 C/ 116071-0 | Q21: REF RECEB - CR: 968 - LC: 2972 - PN: COMANDO DA MARINHA | R21: Recebido | S21: =IF(C21="","",_xlfn.IFNA(_xlfn.XLOOKUP(C21,'CADASTRO CLIENTE'!$B$2:$B$9815,'CADASTRO CLIENTE'!$C$2:$C$9815),"NÃO ENCONTRADO")) -> HNSA
A22: LC | B22: KROMA COMERCIALIZADORA DE ENERGIA LTDA | C22: C02558 | D22: GALPAO TROPEIRO CHURRASCARIA LTDA | K22: 0 | L22: 46205 | M22: 144.73 | N22: 7220.53 | O22: Transferencia | P22: (C) BANCO BRADESCO AG. 2960-2 C/ 116071-0 | Q22: REF RECEB - CR: 314 - LC: 2972 - PN: GALPAO TROPEIRO CHURRASCARIA LTDA | R22: Recebido | S22: =IF(C22="","",_xlfn.IFNA(_xlfn.XLOOKUP(C22,'CADASTRO CLIENTE'!$B$2:$B$9815,'CADASTRO CLIENTE'!$C$2:$C$9815),"NÃO ENCONTRADO")) -> GALPAO TROPEIRO
A23: NS | B23: KROMA COMERCIALIZADORA DE ENERGIA LTDA | C23: C01644 | D23: BCI COMERCIALIZADORA LTDA | F23: 46205 | G23: 46205 | H23: 48338 | I23: 46218 | J23: 46023 | K23: 0 | L23: 46227 | M23: 0 | N23: 3192.3 | O23: Transferencia | P23: (C) BANCO BRADESCO AG. 2960-2 C/ 116071-0 | Q23: REF RECEB - CR: 844 - NF: 48338 - PN: BCI COMERCIALIZADORA LTDA | R23: Recebido | S23: =IF(C23="","",_xlfn.IFNA(_xlfn.XLOOKUP(C23,'CADASTRO CLIENTE'!$B$2:$B$9815,'CADASTRO CLIENTE'!$C$2:$C$9815),"NÃO ENCONTRADO")) -> BCI
A24: NS | B24: KROMA COMERCIALIZADORA DE ENERGIA LTDA | C24: C01592 | D24: JP STEAK HOUSE CUIABA BUFFET E RESTAURANTE LTDA | F24: 46206 | G24: 46206 | H24: 48470 | I24: 46218 | J24: 46023 | K24: 0 | L24: 46237 | M24: 136.94 | N24: 5630.42 | O24: Transferencia | P24: (C) BANCO BRADESCO AG. 2960-2 C/ 116071-0 | Q24: REF RECEB - CR: 938 - NF: 48470 - PN: JP STEAK HOUSE CUIABA BUFFET E RESTAURANTE LTDA | R24: Recebido | S24: =IF(C24="","",_xlfn.IFNA(_xlfn.XLOOKUP(C24,'CADASTRO CLIENTE'!$B$2:$B$9815,'CADASTRO CLIENTE'!$C$2:$C$9815),"NÃO ENCONTRADO")) -> FAVO DE MEL
A25: LC | B25: KROMA COMERCIALIZADORA DE ENERGIA LTDA | C25: C02809 | D25: ARAPUA II SPE S.A. | K25: 0 | L25: 46234 | M25: 0 | N25: 5000000 | O25: Transferencia | P25: (T) BANCO BRADESCO AG. 2960-2 C/ 116071-0 | Q25: REF RECEB - CR: 950 - LC: 2972 - PN: ARAPUA II SPE S.A. | R25: Recebido | S25: =IF(C25="","",_xlfn.IFNA(_xlfn.XLOOKUP(C25,'CADASTRO CLIENTE'!$B$2:$B$9815,'CADASTRO CLIENTE'!$C$2:$C$9815),"NÃO ENCONTRADO")) -> ARAPUA II SPE
A26: NS | B26: KROMA COMERCIALIZADORA DE ENERGIA LTDA | C26: C02882 | D26: INSPIRA NORTE PARTICIPACOES S/A | F26: 46239 | G26: 46239 | H26: 49867 | I26: 46249 | J26: 46023 | K26: 0 | L26: 46251 | M26: 0 | N26: 5312.8 | O26: Transferencia | P26: (C) BANCO BRADESCO AG. 2960-2 C/ 116071-0 | Q26: REF RECEB - CR: 1798 - NF: 49867 - PN: INSPIRA NORTE PARTICIPACOES S/A | R26: Recebido | S26: =IF(C26="","",_xlfn.IFNA(_xlfn.XLOOKUP(C26,'CADASTRO CLIENTE'!$B$2:$B$9815,'CADASTRO CLIENTE'!$C$2:$C$9815),"NÃO ENCONTRADO")) -> REDE INSPIRA UC COD 43
A27: NS | B27: KROMA COMERCIALIZADORA DE ENERGIA LTDA | C27: C01767 | D27: CONDOMINIO DO EDIFICIO EMPRESARIAL JMF E JQM | F27: 46213 | G27: 46213 | H27: 49244 | I27: 46213 | J27: 46023 | K27: 0 | L27: 46213 | M27: 0 | N27: 176226.29 | O27: Transferencia | P27: (C) BANCO BRADESCO AG. 2960-2 C/ 116071-0 | Q27: REF RECEB - CR: 200 - NF: 49244 - PN: CONDOMINIO DO EDIFICIO EMPRESARIAL JMF E JQM | R27: Recebido | S27: =IF(C27="","",_xlfn.IFNA(_xlfn.XLOOKUP(C27,'CADASTRO CLIENTE'!$B$2:$B$9815,'CADASTRO CLIENTE'!$C$2:$C$9815),"NÃO ENCONTRADO")) -> CONDOMÍNIO JMF E JQM
A28: LC | B28: KROMA GESTAO E SERVICOS EM ENERGIA ELETRICA LTDA - EPP | C28: C01739 | D28: RUI BARBOSA DELICATESSEN COMERCIO DE ALIMENTOS LTDA | K28: 0 | L28: 46279 | M28: 0 | N28: 603.73 | O28: Transferencia | P28: (C) BANCO BRADESCO AG. 2960-2 C/ 225-9 | Q28: REF RECEB - CR: 3403 - LC: 11980 - PN: RUI BARBOSA DELICATESSEN COMERCIO DE ALIMENTOS LTDA | R28: Recebido | S28: =IF(C28="","",_xlfn.IFNA(_xlfn.XLOOKUP(C28,'CADASTRO CLIENTE'!$B$2:$B$9815,'CADASTRO CLIENTE'!$C$2:$C$9815),"NÃO ENCONTRADO")) -> RUI BARBOSA DELICATESSEN
A29: NS | B29: KROMA COMERCIALIZADORA DE ENERGIA LTDA | C29: C01813 | D29: SELF IT ACADEMIAS HOLDING S.A. | F29: 46239 | G29: 46239 | H29: 49795 | I29: 46248 | J29: 46023 | K29: 0 | L29: 46244 | M29: 0 | N29: 7437.9 | O29: Transferencia | P29: (C) BANCO BRADESCO AG. 2960-2 C/ 116071-0 | Q29: REF RECEB - CR: 1215 - NF: 49795 - PN: SELF IT ACADEMIAS HOLDING S.A. | R29: Recebido | S29: =IF(C29="","",_xlfn.IFNA(_xlfn.XLOOKUP(C29,'CADASTRO CLIENTE'!$B$2:$B$9815,'CADASTRO CLIENTE'!$C$2:$C$9815),"NÃO ENCONTRADO")) -> SELF IT - P KENNEDY
A30: NS | B30: KROMA COMERCIALIZADORA DE ENERGIA LTDA | C30: C03128 | D30: HOSPITAL VETERINARIO DOK LTDA | F30: 46300 | G30: 46300 | H30: 51489 | I30: 46314 | J30: 46023 | K30: 0 | L30: 46314 | M30: 0 | N30: 965.57 | O30: Transferencia | P30: (C) BANCO BRADESCO AG. 2960-2 C/ 116071-0 | Q30: REF RECEB - CR: 5246 - NF: 51489 - PN: HOSPITAL VETERINARIO DOK LTDA | R30: Recebido | S30: =IF(C30="","",_xlfn.IFNA(_xlfn.XLOOKUP(C30,'CADASTRO CLIENTE'!$B$2:$B$9815,'CADASTRO CLIENTE'!$C$2:$C$9815),"NÃO ENCONTRADO")) -> SER - DOK HOVET GUARULHOS
A31: NS | B31: KROMA COMERCIALIZADORA DE ENERGIA LTDA | C31: C02305 | D31: CNS - CENTRAL DE NUCLEOS SILICIOSOS LTDA | F31: 46237 | G31: 46237 | H31: 49416 | I31: 46249 | J31: 46023 | K31: 0 | L31: 46247 | M31: 0 | N31: 28646.46 | O31: Transferencia | P31: (C) BANCO BRADESCO AG. 2960-2 C/ 116071-0 | Q31: REF RECEB - CR: 1478 - NF: 49416 - PN: CNS - CENTRAL DE NUCLEOS SILICIOSOS LTDA | R31: Recebido | S31: =IF(C31="","",_xlfn.IFNA(_xlfn.XLOOKUP(C31,'CADASTRO CLIENTE'!$B$2:$B$9815,'CADASTRO CLIENTE'!$C$2:$C$9815),"NÃO ENCONTRADO")) -> CNS
A32: NS | B32: KROMA COMERCIALIZADORA DE ENERGIA LTDA | C32: C00873 | D32: MAC 01 - COMERCIALIZADORA DE ENERGIA LTDA | F32: 46237 | G32: 46237 | H32: 49420 | I32: 46244 | J32: 46023 | K32: 0 | L32: 46244 | M32: 0 | N32: 21254 | O32: Transferencia | P32: (C) BANCO BRADESCO AG. 2960-2 C/ 116071-0 | Q32: REF RECEB - CR: 1136 - NF: 49420 - PN: MAC 01 - COMERCIALIZADORA DE ENERGIA LTDA | R32: Recebido | S32: =IF(C32="","",_xlfn.IFNA(_xlfn.XLOOKUP(C32,'CADASTRO CLIENTE'!$B$2:$B$9815,'CADASTRO CLIENTE'!$C$2:$C$9815),"NÃO ENCONTRADO")) -> GOE COMERCIALIZADORA
A33: NS | B33: KROMA COMERCIALIZADORA DE ENERGIA LTDA | C33: C02238 | D33: TREVO INDUSTRIAL DE ACARTONADOS S/A | F33: 46296 | G33: 46296 | H33: 51167 | I33: 46303 | J33: 46023 | K33: 0 | L33: 46303 | M33: 0 | N33: 175909.74 | O33: Transferencia | P33: (C) BANCO BRADESCO AG. 2960-2 C/ 116071-0 | Q33: REF RECEB - CR: 4563 - NF: 51167 - PN: TREVO INDUSTRIAL DE ACARTONADOS S/A | R33: Recebido | S33: =IF(C33="","",_xlfn.IFNA(_xlfn.XLOOKUP(C33,'CADASTRO CLIENTE'!$B$2:$B$9815,'CADASTRO CLIENTE'!$C$2:$C$9815),"NÃO ENCONTRADO")) -> TREVO
A34: LC | B34: KROMA GESTAO E SERVICOS EM ENERGIA ELETRICA LTDA - EPP | C34: C02324 | D34: CONDOMINIO TORRE DOMANI | K34: 0 | L34: 46220 | M34: 0 | N34: 238.37 | O34: Transferencia | P34: (C) BANCO BRADESCO AG. 2960-2 C/ 225-9 | Q34: REF RECEB - CR: 2313 - LC: 11849 - PN: CONDOMINIO TORRE DOMANI | R34: Recebido | S34: =IF(C34="","",_xlfn.IFNA(_xlfn.XLOOKUP(C34,'CADASTRO CLIENTE'!$B$2:$B$9815,'CADASTRO CLIENTE'!$C$2:$C$9815),"NÃO ENCONTRADO")) -> DOMANI
A35: NS | B35: KROMA COMERCIALIZADORA DE ENERGIA LTDA | C35: C03064 | D35: INSPIRA NORTE PARTICIPACOES S/A | F35: 46210 | G35: 46210 | H35: 49028 | I35: 46218 | J35: 46023 | K35: 0 | L35: 46218 | M35: 0 | N35: 4155.8 | O35: Transferencia | P35: (C) BANCO BRADESCO AG. 2960-2 C/ 116071-0 | Q35: REF RECEB - CR: 647 - NF: 49028 - PN: INSPIRA NORTE PARTICIPACOES S/A | R35: Recebido | S35: =IF(C35="","",_xlfn.IFNA(_xlfn.XLOOKUP(C35,'CADASTRO CLIENTE'!$B$2:$B$9815,'CADASTRO CLIENTE'!$C$2:$C$9815),"NÃO ENCONTRADO")) -> REDE INSPIRA - UC COD 31
A36: NS | B36: KROMA COMERCIALIZADORA DE ENERGIA LTDA | C36: C02290 | D36: LEANDRO OLIVEIRA ANDRADE SERVICOS LTDA | F36: 46238 | G36: 46238 | H36: 49689 | I36: 46249 | J36: 46023 | K36: 0 | L36: 46253 | M36: 0 | N36: 2882.18 | O36: Transferencia | P36: (C) BANCO BRADESCO AG. 2960-2 C/ 116071-0 | Q36: REF RECEB - CR: 1933 - NF: 49689 - PN: LEANDRO OLIVEIRA ANDRADE SERVICOS LTDA | R36: Recebido | S36: =IF(C36="","",_xlfn.IFNA(_xlfn.XLOOKUP(C36,'CADASTRO CLIENTE'!$B$2:$B$9815,'CADASTRO CLIENTE'!$C$2:$C$9815),"NÃO ENCONTRADO")) -> LEANDRO OLIVEIRA SERVICOS
A37: NS | B37: KROMA GESTAO E SERVICOS EM ENERGIA ELETRICA LTDA - EPP | C37: C02999 | D37: ROTA PREMIUM VEICULOS LTDA | F37: 46267 | G37: 46267 | H37: 1085 | I37: 46295 | J37: 46023 | K37: 0 | L37: 46294 | M37: 0 | N37: 938.5 | O37: Transferencia | P37: (C) BANCO BRADESCO AG. 2960-2 C/ 225-9 | Q37: REF RECEB - CR: 4057 - NF: 1085 - PN: ROTA PREMIUM VEICULOS LTDA | R37: Recebido | S37: =IF(C37="","",_xlfn.IFNA(_xlfn.XLOOKUP(C37,'CADASTRO CLIENTE'!$B$2:$B$9815,'CADASTRO CLIENTE'!$C$2:$C$9815),"NÃO ENCONTRADO")) -> ROTA PREMIUM
A38: NS | B38: KROMA COMERCIALIZADORA DE ENERGIA LTDA | C38: C01640 | D38: BONANZA SUPERMERCADOS LTDA EM RECUPERACAO JUDICIAL | F38: 46302 | G38: 46302 | H38: 51864 | I38: 46307 | J38: 46023 | K38: 0 | L38: 46308 | M38: 0 | N38: 7270.36 | O38: Transferencia | P38: (C) BANCO BNB AG. 44 C/ 49680-0 | Q38: REF RECEB - CR: 4879 - NF: 51864 - PN: BONANZA SUPERMERCADOS LTDA EM RECUPERACAO JUDICIAL | R38: Recebido | S38: =IF(C38="","",_xlfn.IFNA(_xlfn.XLOOKUP(C38,'CADASTRO CLIENTE'!$B$2:$B$9815,'CADASTRO CLIENTE'!$C$2:$C$9815),"NÃO ENCONTRADO")) -> BONANZA SUPERMERCADOS
A39: NS | B39: FILIAL - PB - KROMA COMERCIALIZADORA DE ENERGIA LTDA | C39: C02912 | D39: COMPANHIA DE AGUA E ESGOTOS DA PARAIBA CAGEPA | F39: 46269 | G39: 46269 | H39: 478 | I39: 46285 | J39: 46023 | K39: 0 | L39: 46283 | M39: 0 | N39: 17325.78 | O39: Transferencia | P39: (C) BANCO BRADESCO AG. 2960-2 C/ 116071-0 | Q39: REF RECEB - CR: 3812 - NF: 478 - PN: COMPANHIA DE AGUA E ESGOTOS DA PARAIBA CAGEPA | R39: Recebido | S39: =IF(C39="","",_xlfn.IFNA(_xlfn.XLOOKUP(C39,'CADASTRO CLIENTE'!$B$2:$B$9815,'CADASTRO CLIENTE'!$C$2:$C$9815),"NÃO ENCONTRADO")) -> CAGEPA
A40: NS | B40: KROMA COMERCIALIZADORA DE ENERGIA LTDA | C40: C01654 | D40: PE ENERGIA SPE S/A | F40: 46232 | G40: 46232 | H40: 49337 | I40: 46233 | J40: 46023 | K40: 0 | L40: 46232 | M40: 0 | N40: 3974831.9 | O40: Transferencia | P40: (C) BANCO ABC AG. 1 C/ 2323822-6 | Q40: REF RECEB - CR: 886 - NF: 49337 - PN: PE ENERGIA SPE S/A | R40: Recebido | S40: =IF(C40="","",_xlfn.IFNA(_xlfn.XLOOKUP(C40,'CADASTRO CLIENTE'!$B$2:$B$9815,'CADASTRO CLIENTE'!$C$2:$C$9815),"NÃO ENCONTRADO")) -> PE ENERGIA SPE
...

Sheet TITULOS ABERTO ANTIGO ATE 30.06
A1: Selection | B1: Filial | C1: Documento | D1: Tipo Documento | E1: Série do Documento | F1: Código Parceiro | G1: Nome Fantasia do Parceiro | H1: Saldo Parcela | I1: Nome Parceiro | J1: CNPJ/CPF | K1: Nº parcela | L1: Valor Parcela | M1: Valor Desconto | N1: Valor Total Juros | O1: Total Pagamento | P1: Total Atualizado | Q1: Moeda | R1: Taxa Moeda | S1: Valor Parcela ME | T1: Saldo Parcela ME | U1: Valor Imposto Retido no Pagamento | V1: Data Documento | W1: Data Vencimento | X1: Dias Atraso | Y1: Observações | Z1: Contrato | AA1: Forma de Pagamento | AB1: Nosso Número | AC1: Número de Controle | AD1: Linha Digitável | AE1: Status Boleto | AF1: Situação Boleto | AG1: Vendedor | AH1: Projeto | AI1: Modelo | AJ1: UF Cobrança | AK1: Município Cobrança | AL1: Total Atualizado ME | AM1: Número da NFS-e | AN1: Ref.1 | AO1: Informação Cobrança | AP1: Forma de Pagamento da Parcela | AQ1: Total Pagamento ME | AR1: Multa % | AS1: Valor Multa | AT1: Valor Multa ME | AU1: Juros % | AV1: Valor Total Juros ME | AW1: Desconto % | AX1: Valor Desconto ME
A2: FALSE | B2: 9 - KROMA GESTAO E SERVICOS EM ENERGIA ELETRICA | C2: 12197 | D2: Lançamento Contábil Manual | E2: 10589 | F2: C03018 | G2: ARAPUA PARTICIPACOES | H2: 26655 | I2: ARAPUA PARTICIPACOES S.A | J2: 43674701000119 | K2: 0 | L2: 26655 | M2: 0 | N2: 0 | O2: 26655 | P2: 26655 | Q2: R$ | R2: 0 | S2: 0 | T2: 0 | U2: 0 | V2: 46203 | W2: 46325 | X2: 113 | Y2: VLR REF SRV GESTAO NF 349 ARAPUA PARTICIPACOES | AE2: Não Informado | AF2: Não Informado | AL2: 0 | AQ2: 0 | AR2: 0 | AS2: 0 | AT2: 0 | AU2: 0 | AV2: 0 | AW2: 0 | AX2: 0
A3: FALSE | B3: 9 - KROMA GESTAO E SERVICOS EM ENERGIA ELETRICA | C3: 12194 | D3: Lançamento Contábil Manual | E3: 10586 | F3: C02693 | G3: TBFORTE - SP | H3: 4728 | I3: TBFORTE SEGURANCA E TRANSPORTE DE VALORES LTDA. | J3: 09262608000169 | K3: 0 | L3: 4728 | M3: 0 | N3: 0 | O3: 4728 | P3: 4728 | Q3: R$ | R3: 0 | S3: 0 | T3: 0 | U3: 0 | V3: 46203 | W3: 46203 | X3: 113 | Y3: VLR REF SRV GESTAO NF 338 TBFORTE - SP | AE3: Não Informado | AF3: Não Informado | AL3: 0 | AQ3: 0 | AR3: 0 | AS3: 0 | AT3: 0 | AU3: 0 | AV3: 0 | AW3: 0 | AX3: 0
A4: FALSE | B4: 9 - KROMA GESTAO E SERVICOS EM ENERGIA ELETRICA | C4: 11898 | D4: Lançamento Contábil Manual | E4: 10291 | F4: C00915 | G4: HOSP. JAYME DA FONTE | H4: 3147.74 | I4: ORGANIZACAO HOSPITALAR DE PERNAMBUCO LTDA | J4: 11.452.240/0001-43 | K4: 0 | L4: 3147.74 | M4: 0 | N4: 0 | O4: 3147.74 | P4: 3147.74 | Q4: R$ | R4: 0 | S4: 0 | T4: 0 | U4: 0 | V4: 46203 | W4: 46022 | X4: 294 | Y4: VLR REF SRV GESTAO NF 8024 HOSP. JAYME DA FONTE | AE4: Não Informado | AF4: Não Informado | AL4: 0 | AQ4: 0 | AR4: 0 | AS4: 0 | AT4: 0 | AU4: 0 | AV4: 0 | AW4: 0 | AX4: 0
A5: FALSE | B5: 9 - KROMA GESTAO E SERVICOS EM ENERGIA ELETRICA | C5: 12189 | D5: Lançamento Contábil Manual | E5: 10581 | F5: C01358 | G5: PRIME SEAFOOD - BA | H5: 3002.79 | I5: PRIME SEAFOOD LTDA | J5: 15452593000366 | K5: 0 | L5: 3002.79 | M5: 0 | N5: 0 | O5: 3002.79 | P5: 3002.79 | Q5: R$ | R5: 0 | S5: 0 | T5: 0 | U5: 0 | V5: 46203 | W5: 46188 | X5: 128 | Y5: VLR REF SRV GESTAO NF 40 PRIME SEAFOOD - BA | AE5: Não Informado | AF5: Não Informado | AL5: 0 | AQ5: 0 | AR5: 0 | AS5: 0 | AT5: 0 | AU5: 0 | AV5: 0 | AW5: 0 | AX5: 0
A6: FALSE | B6: 9 - KROMA GESTAO E SERVICOS EM ENERGIA ELETRICA | C6: 12190 | D6: Lançamento Contábil Manual | E6: 10582 | F6: C02893 | G6: PRIME SEAFOOD - PA | H6: 3002.79 | I6: PRIME SEAFOOD LTDA | J6: 15452593001176 | K6: 0 | L6: 3002.79 | M6: 0 | N6: 0 | O6: 3002.79 | P6: 3002.79 | Q6: R$ | R6: 0 | S6: 0 | T6: 0 | U6: 0 | V6: 46203 | W6: 46188 | X6: 128 | Y6: VLR REF SRV GESTAO NF 90 PRIME SEAFOOD - PA | AE6: Não Informado | AF6: Não Informado | AL6: 0 | AQ6: 0 | AR6: 0 | AS6: 0 | AT6: 0 | AU6: 0 | AV6: 0 | AW6: 0 | AX6: 0
A7: FALSE | B7: 9 - KROMA GESTAO E SERVICOS EM ENERGIA ELETRICA | C7: 11950 | D7: Lançamento Contábil Manual | E7: 10343 | F7: C02188 | G7: MESSEJANA | H7: 2960.97 | I7: MESSEJANA CENTER EMPREENDIMENTOS LTDA | J7: 35364021000170 | K7: 0 | L7: 2960.97 | M7: 0 | N7: 0 | O7: 2960.97 | P7: 2960.97 | Q7: R$ | R7: 0 | S7: 0 | T7: 0 | U7: 0 | V7: 46203 | W7: 46052 | X7: 264 | Y7: VLR REF SRV GESTAO NF 231 MESSEJANA | AE7: Não Informado | AF7: Não Informado | AL7: 0 | AQ7: 0 | AR7: 0 | AS7: 0 | AT7: 0 | AU7: 0 | AV7: 0 | AW7: 0 | AX7: 0
A8: FALSE | B8: 9 - KROMA GESTAO E SERVICOS EM ENERGIA ELETRICA | C8: 12121 | D8: Lançamento Contábil Manual | E8: 10513 | F8: C00871 | G8: CAMPIMAGEM | H8: 2665.26 | I8: CAMPIMAGEM-CENTRO DE DIAG.POR IMAGEM DE CAMP.GRANDE LTDA | J8: 02503493000108 | K8: 0 | L8: 2665.26 | M8: 0 | N8: 0 | O8: 2665.26 | P8: 2665.26 | Q8: R$ | R8: 0 | S8: 0 | T8: 0 | U8: 0 | V8: 46203 | W8: 46142 | X8: 174 | Y8: VLR REF SRV GESTAO NF 1361 CAMPIMAGEM | AE8: Não Informado | AF8: Não Informado | AL8: 0 | AQ8: 0 | AR8: 0 | AS8: 0 | AT8: 0 | AU8: 0 | AV8: 0 | AW8: 0 | AX8: 0
A9: FALSE | B9: 9 - KROMA GESTAO E SERVICOS EM ENERGIA ELETRICA | C9: 12226 | D9: Lançamento Contábil Manual | E9: 10618 | F9: C02103 | G9: ATACADAO DM LTDA | H9: 2579.9 | I9: ATACADAO DM LTDA | J9: 03369825000176 | K9: 0 | L9: 2579.9 | M9: 0 | N9: 0 | O9: 2579.9 | P9: 2579.9 | Q9: R$ | R9: 0 | S9: 0 | T9: 0 | U9: 0 | V9: 46203 | W9: 46203 | X9: 113 | Y9: VLR REF SRV GESTAO NF 385 ATACADAO DM LTDA | AE9: Não Informado | AF9: Não Informado | AL9: 0 | AQ9: 0 | AR9: 0 | AS9: 0 | AT9: 0 | AU9: 0 | AV9: 0 | AW9: 0 | AX9: 0
A10: FALSE | B10: 9 - KROMA GESTAO E SERVICOS EM ENERGIA ELETRICA | C10: 11941 | D10: Lançamento Contábil Manual | E10: 10334 | F10: C02393 | G10: SPP V | H10: 2462.5 | I10: SAO PEDRO E PAULO V ENERGIA SPE S/A | J10: 30997905000149 | K10: 0 | L10: 2462.5 | M10: 0 | N10: 0 | O10: 2462.5 | P10: 2462.5 | Q10: R$ | R10: 0 | S10: 0 | T10: 0 | U10: 0 | V10: 46203 | W10: 46325 | X10: 264 | Y10: VLR REF SRV GESTAO NF 253 SPP V | AE10: Não Informado | AF10: Não Informado | AL10: 0 | AQ10: 0 | AR10: 0 | AS10: 0 | AT10: 0 | AU10: 0 | AV10: 0 | AW10: 0 | AX10: 0
A11: FALSE | B11: 9 - KROMA GESTAO E SERVICOS EM ENERGIA ELETRICA | C11: 12138 | D11: Lançamento Contábil Manual | E11: 10530 | F11: C02393 | G11: SPP V | H11: 2462.5 | I11: SAO PEDRO E PAULO V ENERGIA SPE S/A | J11: 30997905000149 | K11: 0 | L11: 2462.5 | M11: 0 | N11: 0 | O11: 2462.5 | P11: 2462.5 | Q11: R$ | R11: 0 | S11: 0 | T11: 0 | U11: 0 | V11: 46203 | W11: 46325 | X11: 128 | Y11: VLR REF SRV GESTAO NF 62 SPP V | AE11: Não Informado | AF11: Não Informado | AL11: 0 | AQ11: 0 | AR11: 0 | AS11: 0 | AT11: 0 | AU11: 0 | AV11: 0 | AW11: 0 | AX11: 0
A12: FALSE | B12: 9 - KROMA GESTAO E SERVICOS EM ENERGIA ELETRICA | C12: 11881 | D12: Lançamento Contábil Manual | E12: 10274 | F12: C01840 | G12: MR PHARMA | H12: 2373.52 | I12: MR PHARMA S.A | J12: 23668196000192 | K12: 0 | L12: 2373.52 | M12: 0 | N12: 0 | O12: 2373.52 | P12: 2373.52 | Q12: R$ | R12: 0 | S12: 0 | T12: 0 | U12: 0 | V12: 46203 | W12: 46022 | X12: 294 | Y12: VLR REF SRV GESTAO NF 7785 MR PHARMA | AE12: Não Informado | AF12: Não Informado | AL12: 0 | AQ12: 0 | AR12: 0 | AS12: 0 | AT12: 0 | AU12: 0 | AV12: 0 | AW12: 0 | AX12: 0
A13: FALSE | B13: 9 - KROMA GESTAO E SERVICOS EM ENERGIA ELETRICA | C13: 12013 | D13: Lançamento Contábil Manual | E13: 10406 | F13: C01840 | G13: MR PHARMA | H13: 2373.52 | I13: MR PHARMA S.A | J13: 23668196000192 | K13: 0 | L13: 2373.52 | M13: 0 | N13: 0 | O13: 2373.52 | P13: 2373.52 | Q13: R$ | R13: 0 | S13: 0 | T13: 0 | U13: 0 | V13: 46203 | W13: 46112 | X13: 204 | Y13: VLR REF SRV GESTAO NF 772 MR PHARMA | AE13: Não Informado | AF13: Não Informado | AL13: 0 | AQ13: 0 | AR13: 0 | AS13: 0 | AT13: 0 | AU13: 0 | AV13: 0 | AW13: 0 | AX13: 0
... A251: FALSE | B251: 9 - KROMA GESTAO E SERVICOS EM ENERGIA ELETRICA | C251: 12104 | D251: Lançamento Contábil Manual | E251: 10497 | F251: C02408 | G251: FENIX RESIDUOS | H251: 200.67 | I251: FENIX GERENCIAMENTO DE RESIDUOS LTDA | J251: 74077983000109 | K251: 0 | L251: 200.67 | M251: 0 | N251: 0 | O251: 200.67 | P251: 200.67 | Q251: R$ | R251: 0 | S251: 0 | T251: 0 | U251: 0 | V251: 46203 | W251: 46142 | X251: 174 | Y251: VLR REF SRV GESTAO NF 1276 FENIX RESIDUOS | AE251: Não Informado | AF251: Não Informado | AL251: 0 | AQ251: 0 | AR251: 0 | AS251: 0 | AT251: 0 | AU251: 0 | AV251: 0 | AW251: 0 | AX251: 0
M252: =SUBTOTAL(9,M2:M251) -> 0 | N252: =SUBTOTAL(9,N2:N251) -> 0 | O252: =SUBTOTAL(9,O2:O251) -> 4925 | P252: =SUBTOTAL(9,P2:P251) -> 4925 | AL252: =SUBTOTAL(9,AL2:AL251) -> 0 | AQ252: =SUBTOTAL(9,AQ2:AQ251) -> 0 | AS252: =SUBTOTAL(9,AS2:AS251) -> 0 | AT252: =SUBTOTAL(9,AT2:AT251) -> 0 | AV252: =SUBTOTAL(9,AV2:AV251) -> 0 | AX252: =SUBTOTAL(9,AX2:AX251) -> 0

Sheet CADASTRO CLIENTE
A1: Nome do PN | B1: Código do PN | C1: Nome Fantasia | D1: CPF/CNPJ | E1: Saldo da conta
A2: 1 OFICIO DE NOTAS DO RECIFE | B2: F06107 | E2: 0
A3: 1 TABELIONATO DE PROTESTO DA COMARCA DE | B3: F04857 | C3: 1 TABELIONATO DE PROTESTO DO RECIFE | D3: 28.993.451/0001-96 | E3: 0
A4: 1 TABELIONATO DE PROTESTO DO RECIFE | B4: F04638 | C4: 1 TABELIONATO DE PROTESTO DO RECIFE | D4: 52.945.080/0001-51 | E4: 0
A5: 1, 2, 3 MARKETING DE EVENTOS LTDA | B5: F04335 | C5: 1, 2, 3 MARKETING DE EVENTOS LTDA | D5: 10.414.014/0001-05 | E5: 0
A6: 1. SERVICO NOTARIAL E DE REGISTROS | B6: F04722 | C6: CARTORIO ANTONIA DE CAMPOS MACIEL | D6: 00.964.635/0001-09 | E6: 0
A7: 1001 INFORMATICA 1001 SOLUCOES EM INFORM | B7: F03187 | C7: 1001 INFORMATICA 100 | D7: 40.873.358/0001-43 | E7: 0
A8: 11 SUPERINTENDENCIA DE POLICIA RODOVIARI | B8: F03513 | C8: 11 SUPERINTENDENCIA | D8: 00.394.494/0108-75 | E8: 0
A9: 2 OFICIO DE REG DE TITULOS DOC E CIVIL | B9: F04587 | C9: 2 OFICIO DE REG DE TITULOS DOC E CIVIL | D9: 41.322.339/0001-91 | E9: 0
A10: 2.0 HOTEIS BOA VISTA | B10: F04102 | C10: 2.0 HOTEIS BOA VISTA | D10: 17.505.303/0001-69 | E10: 0
A11: 2PAR GESTAO EM NEGOCIOS S/S LTDA | B11: F03416 | C11: 2PAR GESTAO EM NEGO | D11: 18.071.838/0001-31 | E11: 0
A12: 2W ECOBANK S.A. | B12: C01279 | C12: 2W ENERGIA | D12: 8773135000100 | E12: 0
A13: 2W ECOBANK S.A. | B13: F01332 | C13: 2W ENERGIA | D13: 8773135000100 | E13: 0
A14: 2º REGISTRO DE TITULOS E DOC E REG CIVIL | B14: F05285 | C14: 2º REGISTRO DE TITULOS E DOCUMENTOS E RE | D14: 54.813.099/0001-70 | E14: 0
A15: 2º TABELIONATO DE NOTAS E OFICIO DE REGI | B15: F05267 | C15: 2º TABELIONATO DE NOTAS E OFICIO DE REGI | D15: 05.614.888/0001-76 | E15: 0
A16: 3 ON COMERCIO E SERV EM TEC EIRELI | B16: F05274 | C16: 3 ON COMERCIO E SERV EM TEC EIRELI | D16: 31.924.265/0001-00 | E16: 0
A17: 3 TABELIONATO DE PROTESTO DE RECIFE | B17: F04855 | C17: 3 TABELIONATO DE PROTESTO DE RECIFE | D17: 29.640.584/0001-41 | E17: 0
A18: 3 TABELIONATO DE PROTESTO DE TITULOS E D | B18: F04517 | C18: 3 TABELIONATO DE PROTESTO DE TITULOS E D | D18: 30.672.081/0001-37 | E18: 0
A19: 3 TABELIONATO NOTAS PROTESTO TITULOS REG | B19: F04625 | C19: CARTORIO FRANCISCO XIMENES DE MELO | D19: 01.730.807/0001-42 | E19: 0
A20: 3A MINING S.A. | B20: C02871 | C20: 3A MINING | D20: 14482711000235 | E20: 0
A21: 3A MINING S.A. | B21: F01578 | C21: 3A MINING | D21: 14482711000235 | E21: 0
A22: 3G - TERCEIRA GERACAO COMERCIALIZADORA DE ENERGIA LTDA | B22: C01306 | C22: 3G COMERCIALIZADORA | D22: 17838938000188 | E22: 0
A23: 3G - TERCEIRA GERACAO COMERCIALIZADORA DE ENERGIA LTDA | B23: F01997 | C23: 3G COMERCIALIZADORA | D23: 17838938000188 | E23: 0
A24: 3R EMPREENDIMENTOS R A CASTRO DOS SANTOS | B24: F03514 | C24: 3R EMPREENDIMENTOS R | D24: 15.012.245/0001-06 | E24: 0
A25: 3RIOS FIBRAS E RESINAS LTDA | B25: C01572 | C25: 3RIOS | D25: 29928004000116 | E25: 0
A26: 3RIOS FIBRAS E RESINAS LTDA | B26: F02234 | C26: 3RIOS | D26: 29928004000116 | E26: 0
A27: 3TEC LTDA | B27: F05006 | C27: 3TEC LTDA ETIQUETAS E PLAQUETAS | D27: 00.329.754/0001-90 | E27: 0
A28: 4 TABELIONATO DE PROTESTO DE RECIFE | B28: F04878 | C28: 4 TABELIONATO DE PROTESTO DE RECIFE | D28: 28.922.067/0001-00 | E28: 0
A29: 4A DIVISAO - INDUSTRIA E COMERCIO DE MOVEIS LTDA | B29: C02669 | C29: QUARTA DIVISAO | D29: 66550492000105 | E29: 0
A30: 4A DIVISAO - INDUSTRIA E COMERCIO DE MOVEIS LTDA | B30: F03122 | C30: QUARTA DIVISAO | D30: 66550492000105 | E30: 0
A31: 4M - TREINAMENTOS EMPRESARIAIS E ASSESSO | B31: F04108 | C31: 4M - TREINAMENTOS | D31: 06.556.167/0001-10 | E31: 0
A32: 50.826.642 EMANUELA BEZERRA JESSE | B32: F05043 | C32: EMANUELA B JESSE | D32: 50.826.642/0001-12 | E32: 0
A33: 53.653.386 EDUARDO COSTA CUNHA | B33: F05417 | C33: 53.653.386 EDUARDO COSTA CUNHA | D33: 53.653.386/0001-05 | E33: 0
A34: 59.426.154 HITALLO JEAN DE HOLANDA FREIT | B34: F05424 | C34: 59.426.154 HITALLO JEAN DE HOLANDA FREIT | D34: 59.426.154/0001-92 | E34: 0
A35: 88 ENERGIA S.A. | B35: C00889 | C35: 88 ENERGIA | D35: 28185217000132 | E35: 3230000.2
A36: 88 ENERGIA S.A. | B36: F02353 | C36: 88 ENERGIA | D36: 28185217000132 | E36: 0
A37: A & L DESIGNER SERVICOS E REP. EIRELI | B37: F04229 | C37: A & L DESIGNER SERVICOS E REP. EIRELI | D37: 15.594.950/0001-69 | E37: 0
A38: A A DE CARVALHO SERVICOS DE DESPACHOS EI | B38: F04671 | C38: A A DE CARVALHO SERVICOS DE DESPACHOS EI | D38: 23.352.218/0001-00 | E38: 0
A39: A BATISTA DOS SANTOS COMERCIO | B39: F04110 | C39: FLORICULTURA PARK DAS FLORES | D39: 18.738.113/0001-54 | E39: 0
A40: A DE M MARTINS ALVES | B40: F05635 | C40: A DE M MARTINS ALVES | D40: 13.767.337/0001-70 | E40: 0
...
